# 파이썬 버그 코드 - 파이썬 개발자가 만드는 10가지 실수

(출처 : https://www.toptal.com/python/top-10-mistakes-that-python-programmers-make)

### 실수 1 : 함수 인자의 기본값을 설정할 때 잘못된 표현식

파이썬은 함수 인자의 기본값을 설정할 수 있는 기능을 제공한다. 이는 매우 유용한 기능이지만 기본값이 변형가능한(Mutable) 값일 때 혼란을 일으킨다.

```python
def foo(bar=[]): # bar의 값이 입력되지 않는다면 [] 값을 사용한다.
    bar.append("baz")
    return bar

foo() # ['baz'] # 좋아, 잘 작동하는군.
foo() # ['baz', 'baz'] # ?
foo() # ['baz', 'baz', 'baz'] # ?????
```

왜 foo가 호출될 때마다 bar는 새로운 리스트를 생성하지 않고 동일한 리스트를 재사용하는 것일까? 좀 더 파이썬 프로그래밍 관점에서 접근해보자. 파이썬에서 함수 인자의 기본값은 처음에 함수가 정의 될 때 '**한번만**' 실행된다. 따라서, 함수 foo의 인자 bar는 함수 foo가 처음 정의 될 때 한번만 초기화되므로(함수 호출시마다가 아니다!) 함수 foo를 여러번 호출하더라도 동일한 리스트를 재사용하는 것이다.

위 문제를 해결하기 위해서는 함수 코드에서 기본값을 초기화하는 코드를 추가하면 된다.

```python
def foo(bar=None): # bar의 기본값을 None으로 지정
    if bar is None: # bar의 값이 None이라면 == bar의 값이 입력되지 않았다면
        bar = [] # bar를 빈 리스트로 '초기화'한다.
    bar.append("baz")
    return bar

foo() # ['baz']
foo() # ['baz']
foo() # ['baz'] # 문제 해결!
```



### 실수 2 : 잘못된 클래스 변수 사용

다음 예제를 보자.

```python
class A(object):
    x = 1
    
class B(A): # A를 상속받는다.
    pass

class C(A): # A를 상속받는다.
    pass

print(A.x, B.x, C.x) # 1 1 1
```

논리적으로 맞다.

```python
B.x = 2
print(A.x, B.x, C.x) # 1 2 1
```

아직까진 예상대로다.

```python
A.x = 3
print(A.x, B.x, C.x) # 3 2 3 # ???
```

A의 x 프로퍼티를 바꿨는데 C의 x 프로퍼티도 함께 바뀌었다. 왜일까?

파이썬에서 클래스 변수들은 MRO(Method Resolution Order)에 따라 내부적으로 딕셔너리로 다루어진다. 상기 코드에서 클래스 C는 x 프로퍼티를 가지고있지 않아 C의 기본 클래스에 해당하는 A의 x 프로퍼티를 참조하게 된다. 클래스 B는 상기 코드에서 x 프로퍼티를 정의했기 때문에 A의 x 프로퍼티가 바뀌어도 영향을 받지 않는다.



### 실수 3 : 예외 블록에서의 잘못된 파라미터 정의

```python
# 잘못된 코드
try:
    l = ['a', 'b']
    int(l[2])
except ValueError, IndexError: # 에러 처리가 되지 않는다!
    pass
```

다중 예외처리 코드를 작성할 때는 튜플로 묶어줘야하며, as 키워드로 얼라이어싱이 가능하다.

```python
# 올바른 코드
try:
    l = ['a', 'b']
    int(l[2])
except (ValueError, IndexError) as e:
    pass
```



### 실수 4 : 파이썬 스코프 룰에 대한 잘못된 이해

파이썬 스코프 룰은 **LEGB**룰로 잘 알려졌는데, 이는 **L**ocal(지역), **E**nclosing(내장), **G**lobal(전역), **B**uilt-in(빌트인)의 첫 글자를 따온 것이다. 여기서 다음 예제를 보자.

```python
x = 10
def foo():
    x += 1
    print(x)
foo() # UnboundLocalError: local variable 'x' referenced before assignment
```

왜 이러한 문제가 발생하는 것일까? 이는 파이썬에서 변수에 대한 할당문이 실행될 때 암시적으로 스코프의 범위가 현재 코드가 실행되는 지역 스코프로 정의되고 외부 스코프의 변수는 숨겨지기 때문이다.

이런 경우는 리스트를 사용할 때 자주 발생한다. 다음 예제를 보자.

```python
lst = [1, 2, 3]
def foo1():
    lst.append(5)
foo1() # 잘 작동한다!
print(lst)

lst = [1, 2, 3]
def foo2():
    lst += [5]
foo2() # UnboundLocalError: local variable 'lst' referenced before assignment
print(lst)
```

foo1에서는 리스트의 append 메서드를 통해 변형이 이루어지므로 할당문이 실행되지 않는다. 하지만, foo2에서는 `lst += [5]`는 `lst = lst + [5]`이므로 할당문이 실행된다. 이 과정에서 변수 lst의 스코프 범위는 함수의 지역 스코프로 한정되므로 전역 스코프에 존재하는 변수 lst를 참조할 수 없다. 그렇기 때문에 에러가 발생하는 것이다.



### 실수 5 : 순회 과정 중에 리스트 요소 변경

```python
odd = lambda x : bool(x % 2)
numbers = [n for n in range(10)]
for i in range(len(numbers)):
    if odd(numbers[i]):
        del numbers[i] # 순회 과정 중에 리스트 값을 제거한다.
'''
Traceback (most recent call last):
  	  File "<stdin>", line 2, in <module>
IndexError: list index out of range
'''
```

위의 코드는 명백히 문제점이 보이지만 실제로 숙련된 파이썬 개발자라도 의도적이지 않게 순회 과정 중에 리스트 요소를 변경하는 실수를 저지르기도 한다.

다행히도, 파이썬은 코드를 간결화하면서 위와 같은 실수를 피하기 위한 우아한 패러다임을 몇가지 제시하는데, 리스트 컴프리헨션이 그중 하나다.

```python
odd = lambda x : bool(x % 2)
numbers = [n for n in range(10)]
numbers[:] = [n for n in numbers if not odd(n)]
print(numbers) # [0, 2, 4, 6, 8]
```



### 실수 6 : 클로저에서 파이썬이 어떻게 변수 바인딩을 실행하는가

```python
def create_multipliers():
    return [lambda x : i * x for i in range(5)]
for multiplier in create_multipliers():
    print(multiplier(2))
'''
8
8
8
8
8
'''
```

이러한 일이 발생하는 이유는 파이썬의 늦은 바인딩(Late Binding) 때문인데, 내재된 함수가 호출되기 전에 클로저에 있는 변수 값을 참조하는 것을 의미한다. 따라서 위의 코드에서 함수가 호출될 때마다 변수 i 값이 반환되었다가 마지막에 변수 i에 4가 할당되어 모든 결과가 8이 나온 것이다.

다음과 같이 간단한 트릭으로 이 문제를 해결할 수 있다.

```python
def create_multipliers():
    return [lambda x : i = i * x for i in range(5)]
for multiplier in create_multipliers():
    print(multiplier(2))
'''
0
2
4
6
8
'''
```

익명 함수를 생성할 때 기본 인자를 지정하는 방법의 장점을 활용하여 문제를 해결하였다.



### 실수 7 : 모듈간 환형 의존 구조

`a.py`파일과 `b.py`파일이 있다고 가정하자.

`a.py`

```python
import b

def f():
    return b.x

print(f())
```

`b.py`

```python
import a

x = 1

def g():
    print(a.f())
```

먼저 `a.py`를 임포트해보자.

```python
import a # 1
```

잘 작동한다. 분명 이번 절의 주제에서 모듈간 환형 의존 구조는 문제가 된다고 했는데 잘 작동한다니 이상하지 않은가?

정답은 '환형 의존 구조의 존재 여부와 그 자체가 파이썬에서 문제되지는 않는다'이다. 만약 모듈이 이미 임포트되어있는 상황이라면 파이썬은 영리하게도 모듈을 다시 임포트하지 않는다. 하지만, 각각의 모듈에 있는 함수와 변수가 다른 모듈에 정의된 함수와 변수에 접근하려고 할 때 문제가 발생할 것이다.

따라서 `a.py`를 임포트한다면 `b.py` 역시 `a.py` 내에서 문제없이 임포트 될 것이다. 왜냐하면 `b.py`는 임포트 되는 시점에서 `a.py`의 함수와 변수를 참조하지 않기 때문이다. 단지 임포트 된 뒤에 `a.py`에 있는 f() 함수를 호출할 뿐이다.

하지만 `b.py`를 임포트한다면 어떻게 될까?

```python
import b
'''
Traceback (most recent call last):
  	  File "<stdin>", line 1, in <module>
  	  File "b.py", line 1, in <module>
    import a
  	  File "a.py", line 6, in <module>
	print f()
  	  File "a.py", line 4, in f
	return b.x
AttributeError: 'module' object has no attribute 'x'
'''
```

에러가 발생한다! 과정을 차근차근 살펴보자.

`b.py`가 임포트되고 `b.py`는 `a.py`를 임포트한다. `a.py`에서 f() 함수를 호출할 때 문제가 발생한다. f() 함수는 `b.py`의 변수 x를 참조하지만, `b.py`가 `a.py`를 임포트하는 시점에선 변수 x가 정의되지 않았기 때문이다!

이 문제를 해결하는 가장 쉬운 방법은 `b.py`에서 `a.py`를 임포트하는 구문을 변수가 정의된 이후의 시점으로 옮기면 된다.

`b.py`

```python
x = 1

def g():
    import a
    print(a.f())
```



### 실수 8 : 파이썬 기본 라이브러리 모듈과 이름 충돌

파이썬의 장점 중 하나는 '별도의 전처리(설치)가 없어도' 다양한 모듈들을 사용할 수 있다는 점이다. 하지만, 이 때문에 개발자가 의식을 하지 않고 모듈을 사용하다 보면 서로 다른 모듈 및 모듈과 작성한 코드(변수명, 함수명 등) 간에 이름 충돌이 일어날 수 있다.

이는 형편없는 문제를 일으킬 소지가 있다. 대표적으로 모듈이 또 다른 모듈의 코드를 참조하고 있을 때, 변수명 및 함수명을 어떤 모듈의 이름을 참조하는가가 있다. 이는 모듈 버전 및 파이썬 내장 라이브러리를 사용하는 과정에서 자주 일어나는 실수다. 그러므로 파이썬 내장 기본 모듈을 사용할 때는 동일한 이름을 사용하지 않도록 주의해야 한다.



### 실수 9 : 파이썬 2와 파이썬 3의 차이를 이해하지 못함

`foo.py`란 파일이 있다.

```python
import sys

def bar(i):
    if i == 1:
        raise KeyError(1)
    if i == 2:
        raise ValueError(2)

def bad():
    e = None
    try:
        bar(int(sys.argv[1]))
    except KeyError as e:
        print('key error')
    except ValueError as e:
        print('value error')
    print(e)

bad()
```

파이썬 2에서는 다음과 같이 작동한다.

```bash
$ python foo.py 1
key error
1
$ python foo.py 2
value error
2
```

파이썬 3에서는 어떻게 작동할까?

```bash
$ python3 foo.py 1
key error
Traceback (most recent call last):
  File "foo.py", line 19, in <module>
    bad()
  File "foo.py", line 17, in bad
    print(e)
UnboundLocalError: local variable 'e' referenced before assignment
```

무슨 문제가 발생한 것일까? Python 3에서는 `except` 블록 스코프 내에서 예외 객체에 접근할 수 없다.(그렇지 않으면 환형참조(reference cycle)이 발생하여 가비지 콜렉터가 정상적으로 작동하지 않아 메모리 누수가 발생한다.)

이와 같은 이슈를 피하기 위한 하나의 방법으로는 `except` 블록 외부 스코프에서 예외 객체에 접근하는 것이다.

```python
import sys

def bar(i):
    if i == 1:
        raise KeyError(1)
    if i == 2:
        raise ValueError(2)

def good():
    exception = None
    try:
        bar(int(sys.argv[1]))
    except KeyError as e:
        exception = e # exception 변수에 외부 스코프에 있는 예외 객체 e를 할당한다.
        print('key error')
    except ValueError as e:
        exception = e
        print('value error')
    print(exception)

good()
```

다시 파이썬 3로 실행해보자.

```bash
$ python3 foo.py 1
key error
1
$ python3 foo.py 2
value error
2
```

정상적으로 잘 작동한다!



### 실수 10 : `__del__` 메서드를 잘못 사용

`mod.py` 파일은 다음과 같다.

```python
import foo

class Bar(object):
   	    ...
    def __del__(self):
        foo.cleanup(self.myhandle)
```

그리고 `another_mod.py` 파일에서 다음과 같이 실행시키려 한다.

```python
import mod
mybar = mod.Bar()
```

코드를 실행하면 `AttributeError` 예외가 발생한다.

무슨 문제가 발생한 것일까? 파이썬은 인터프리터가 종료될 때 모듈의 전역 변수들은 모두 `None`으로 설정된다. 결과적으로 상기 코드에서 `__del__` 메서드가 실행될 때는 이미 `foo`는 `None`으로 설정된 상태다.

문제에 대한 해결 방법중 하나로는 `atexit.register()` 메서드를 대신 사용하는 것이다. 이 방법을 통해 프로램이 종료 될 때, 인터프리터가 종료 되기 전에 등록된 핸들러가 실행될어 예외가 발생하지 않는다.

```python
import foo
import atexit

def cleanup(handle):
    foo.cleanup(handle)

class Bar(object):
    def __init__(self):
        ...
        atexit.register(cleanup, self.myhandle)
```

이러한 구현은 일반 프로그램 종료 시에 필요한 기능들을 정리하는 깔끔하고 신뢰할 수 있는 방법을 제공한다. 명백하게도, `self.myhandle`에 바인딩 될 객체를 가지고 어떤 작업을 할지는 `foo.cleanup`에서 결정되며, 이는 코드를 작성하는 개발자의 몫이다.